[2024-05-03T13:27:44.423+0000] {task_context_logger.py:104} ERROR - Executor reports task instance <TaskInstance: etl.upload_file_name scheduled__2024-05-01T00:00:00+00:00 [queued]> finished (failed) although the task says it's queued. (Info: None) Was the task killed externally?
